WARNING  python29:jks_login.py:25 可能未成功进入页面【: http://jenkins.senguo.me/login?from=%2F】，可能会引发异常!
WARNING  python29:daily_static_page.py:24 可能未成功进入页面【每日统计更新: http://jenkins.senguo.me/view/%E7%BB%9F%E8%AE%A1%E4%BB%BB%E5%8A%A1/job/UTIL-PF%EF%BC%9A%E6%AF%8F%E6%97%A5%E7%BB%9F%E8%AE%A1%E6%9B%B4%E6%96%B0/build?delay=0sec】，可能会引发异常!
INFO     python29:test_statistic.py:24 店铺id2657,days:101,剩余91
WARNING  urllib3.connectionpool:connectionpool.py:781 Retrying (Retry(total=2, connect=None, read=None, redirect=None, status=None)) after connection broken by 'NewConnectionError('<urllib3.connection.HTTPConnection object at 0x111fe06d0>: Failed to establish a new connection: [Errno 54] Connection reset by peer')': /session/1c65dd6082c491f096d91521aa420614/url
WARNING  urllib3.connectionpool:connectionpool.py:781 Retrying (Retry(total=1, connect=None, read=None, redirect=None, status=None)) after connection broken by 'NewConnectionError('<urllib3.connection.HTTPConnection object at 0x111fe0290>: Failed to establish a new connection: [Errno 61] Connection refused')': /session/1c65dd6082c491f096d91521aa420614/url
WARNING  urllib3.connectionpool:connectionpool.py:781 Retrying (Retry(total=0, connect=None, read=None, redirect=None, status=None)) after connection broken by 'NewConnectionError('<urllib3.connection.HTTPConnection object at 0x111fe0e50>: Failed to establish a new connection: [Errno 61] Connection refused')': /session/1c65dd6082c491f096d91521aa420614/url
INFO     python29:conftest.py:31 退出浏览器img...
WARNING  urllib3.connectionpool:connectionpool.py:781 Retrying (Retry(total=2, connect=None, read=None, redirect=None, status=None)) after connection broken by 'NewConnectionError('<urllib3.connection.HTTPConnection object at 0x111fe0a10>: Failed to establish a new connection: [Errno 61] Connection refused')': /session/1c65dd6082c491f096d91521aa420614
WARNING  urllib3.connectionpool:connectionpool.py:781 Retrying (Retry(total=1, connect=None, read=None, redirect=None, status=None)) after connection broken by 'NewConnectionError('<urllib3.connection.HTTPConnection object at 0x112335890>: Failed to establish a new connection: [Errno 61] Connection refused')': /session/1c65dd6082c491f096d91521aa420614
WARNING  urllib3.connectionpool:connectionpool.py:781 Retrying (Retry(total=0, connect=None, read=None, redirect=None, status=None)) after connection broken by 'NewConnectionError('<urllib3.connection.HTTPConnection object at 0x112335e90>: Failed to establish a new connection: [Errno 61] Connection refused')': /session/1c65dd6082c491f096d91521aa420614
INFO     python29:conftest.py:33 浏览器退出成功.